Workbook

Sheet Жами топшириқлар-1
A1: Вилоят ҳокими У.Қосимов томонидан ҳудудларни ўрганиш давомида аниқланган муаммоларни бартараф этиш бўйича берилаётган тезкор топшириқларнинг ижроси тўғрисида МАЪЛУМОТ (10.11.2025)
A2: Банд | B2: Топшириқ берилган сана | C2: Топшириқ берилган жой | D2: Топшириқ мазмуни | E2: Ижро муддати | F2: Назорат ҳолати | G2: Асосий ижрочи маъсуллар | H2: Вилоят ҳокимлиги, шаҳар ва туман ҳокимликларидан масъуллар | I2: Ижро ҳолати | J2: Изох | M2: Ойлар кесимида | N2: Мажмуалар ва туманлар | P2: =SUM(P3:P1048576) -> 0 | Q2: 45066 | R2: Чоршанба кунгача | T2: Кўриб чиқиш | V2: мчс
A3: 1 | B3: 44922 | C3: Мажмуа ва ташкилотлар | D3: Куз-қиш бўйича тузилган штабларга келиб тушган, назоратга олинган ва ечилган мурожаатларни бўйича ҳарбийларни бириктириш. | E3: 44936 | G3: Вилоят ҳокимлиги гуруҳ раҳбари А.Каримов | H3: З.Назаров | I3: Бажарилган | M3: Январ | N3: Мажмуалар | O3: 1 | P3: =+O3-A3 -> 0 | T3: =+I3 -> Бажарилган
A4: 2 | B4: 44922 | C4: Мажмуа ва ташкилотлар | D4: Ишлаб чиқариш йирик лойиҳаларни шакллантириб, лойиҳа ташабускорлар билан учрашув ўтказиш. | E4: 44931 | G4: Марказий банк вилоят бош бошқармаси (А.Тўхтаев) | H4: Ш.Жўраев | I4: Бажарилган | M4: Январ | N4: Мажмуалар | O4: =+O3+1 -> 2 | P4: =+O4-A4 -> 0 | T4: =+J4 -> 0
A5: 3 | B5: 44922 | C5: Мажмуа ва ташкилотлар | D5: Ҳудудларга тўғридан-тўғри инвестицияларни жалб қилиш, экспорт прогноз режасини ҳафталик ва ойлик графикларини туман (шаҳар) ва секторлар кесимида ишлаб чиқсин, прогнозларнинг бажарилишини назорат қилиш. | E5: 45092 | F5: Доимий | G5: Вилоят ҳокимининг ўринбосари А.Орипов | H5: Ш.Жўраев | I5: Бажарилган | M5: Январ | N5: Мажмуалар | O5: =+O4+1 -> 3 | P5: =+O5-A5 -> 0 | T5: =+J5 -> 0
A6: 4 | B6: 44923 | C6: Термиз шаҳар | D6: Термиз иқтисодий зона ва кичик саноат зоналари фаолиятини яхшилаш, бўш турган ер майдонларини тадбиркорлик фаолиятини йўлга қўйиш, ҳамда ишлаб чиқариш лойиҳаларини амалга ошириш. | E6: 45092 | F6: Доимий | G6: “Термиз” эркин иқтисодий зонаси Дирекцияси ДУК (Б.Жумаев),“Кичик саноат зоналарини бошқариш ягона дирекцияси” (Б.Ортиқов) | H6: Ш.Жўраев | I6: Бажарилган | M6: Январ | N6: Мажмуалар | O6: =+O5+1 -> 4 | P6: =+O6-A6 -> 0 | T6: =+J6 -> 0
A7: 5 | B7: 44923 | C7: Термиз шаҳар | D7: Термиз шаҳар ва туманларда янги кичик саноат зоналарини ташкил этиш таклифларини ишлаб чиқиш. | E7: 44931 | G7: “Кичик саноат зоналарини бошқариш ягона дирекцияси” (Б.Ортиқов) Термиз шаҳар ва туманлар ҳокимликлари | H7: Ш.Жўраев | I7: Бажарилган | M7: Январ | N7: Мажмуалар | O7: =+O6+1 -> 5 | P7: =+O7-A7 -> 0 | T7: =+J7 -> 0
A8: 6 | B8: 44923 | C8: Термиз шаҳар | D8: “Термиз халқаро савдо маркази” ЭСЗни ишга тушириш, муаммоли масалаларнинг тезкор ечимига қаратилган таклифлар ишлаб чиқиб, вилоят ҳокимига ахборот бериш. | E8: 44929 | G8: Вилоят ҳокимининг ўринбосари А.Орипов | H8: Ш.Жўраев | I8: Бажарилган | M8: Январ | N8: Мажмуалар | O8: =+O7+1 -> 6 | P8: =+O8-A8 -> 0 | T8: =+J8 -> 0
A9: 7 | B9: 44923 | C9: Термиз шаҳар | D9: “Термиз халқаро савдо маркази” ЭСЗнинг қурилиши учун олинган кредит маблағларини қайтариш муддатини узайтириш бўйича алоқадор вазирлик ва идоралар билан ҳамкорликда ишларни ташкил этиш. | E9: 44957 | G9: Вилоят ҳокимининг ўринбосари А.Орипов | H9: Ш.Жўраев | I9: Бажарилган | M9: Январ | N9: Мажмуалар | O9: =+O8+1 -> 7 | P9: =+O9-A9 -> 0 | T9: =+J9 -> 0
A10: 8 | B10: 44923 | C10: Термиз шаҳар | D10: Вилоят тадбиркорлари томонидан Покистондан импорт қилиб олиб келинаётган картошка маҳсулотларини олиб киришда юзага келаётган муаммоларни таҳлил қилиш ва ҳал этиш чораларини кўриш. | E10: 44931 | G10: Вилоят ҳокимининг ўринбосари А.Орипов | H10: Ш.Жўраев | I10: Бажарилган | M10: Январ | N10: Мажмуалар | O10: =+O9+1 -> 8 | P10: =+O10-A10 -> 0 | T10: =+J10 -> 0
A11: 9 | B11: 44923 | C11: Термиз шаҳар | D11: “Термиз” ЭИЗдаги бўш турган ер майдонлари (лотлар)ни аукцион савдоларига чиқариш ишларини жадаллаштириш. | E11: 44959 | G11: Вилоят ҳокимининг ўринбосари А.Орипов, “Термиз” ЭИЗ дирекцияси ДУК (Жумаев) | H11: Ш.Жўраев | I11: Бажарилган | M11: Январ | N11: Мажмуалар | O11: =+O10+1 -> 9 | P11: =+O11-A11 -> 0 | T11: =+J11 -> 0
A12: 10 | B12: 44923 | C12: Термиз шаҳар | D12: “Термиз” ЭИЗдаги ер майдонларини (лотлар)ни тижорат банклари кесимида бириктириш ва истиқболли лойиҳа таклифларини ишлаб чиқиш. | E12: 44941 | G12: Вилоят ҳокимининг ўринбосари А.Орипов, “Термиз” ЭИЗ дирекцияси ДУК (Жумаев), Марказий банк бош бошқармаси (Тўхтаев) ва тижорат банклари | H12: Ш.Жўраев | I12: Бажарилган | M12: Январ | N12: Мажмуалар | O12: =+O11+1 -> 10 | P12: =+O12-A12 -> 0 | T12: =+J12 -> 0
A13: 11 | B13: 44925 | C13: Денов тумани | D13: “Денов текстил кластер” МЧЖ (97-844-00-00) томонидан амалга оширилаётган инвестиция лойиҳасини муддатида ишга туширилиши учун кредит маблағлари ажратилишини ҳал этиш. | E13: 45285 | F13: Охирги муддат бошқа узайтирилмайди | G13: Ташқи иқтисодий фаолият Миллий банки АЖ филиали (Ш.Жумаев). | H13: Ш.Жўраев | I13: Бажарилган | J13: 08.08.2023 й кун ҳолатига келиб хам тадбиркор кредит қарздорлигини тўламаган. "Денов текстил кластер" МЧЖ ва Ўзмиллийбанк АЖ ўртасида "Саноат ипотекаси" ҳисобидан 25 млн АҚШ долл миқдорида молиялаштириш лойихаси ишлари амалга оширилмоқда. Лойихани 1-босқичини 2023 йил 4-чорагида молиялаштириш режалаштириляпти. Охирги муддат берилди бошқа узайтирилмайди | M13: Январ | N13: Мажмуалар | O13: =+O12+1 -> 11 | P13: =+O13-A13 -> 0 | T13: =+J13 -> 08.08.2023 й кун ҳолатига келиб хам тадбиркор кредит қарздорлигини тўламаган. "Денов текстил кластер" МЧЖ ва Ўзмиллийбанк АЖ ўртасида "Саноат ипотекаси" ҳисобидан 25 млн АҚШ долл миқдорида молиялаштириш лойихаси ишлари амалга оширилмоқда. Лойихани 1-босқичини 2023 йил 4-чорагида молиялаштириш режалаштириляпти. Охирги муддат берилди бошқа узайтирилмайди
A14: 12 | B14: 44925 | C14: Денов тумани | D14: “Денов текстил кластер” МЧЖ томонидан 2 гектар майдонда гул етиштириш учун иссиқхона ташкил этиш бўйича лойиҳа тақдимотини ўтказиш. | E14: 44944 | G14: Вилоят ҳокимнинг ўринбосари А.Орипов Денов тумани ҳокимлиги (Алламуродов), “Денов текстил кластер” МЧЖ | H14: Ш.Жўраев | I14: Бажарилган | M14: Январ | N14: Мажмуалар | O14: =+O13+1 -> 12 | P14: =+O14-A14 -> 0 | T14: =+J14 -> 0
A15: 13 | B15: 44925 | C15: Денов тумани | D15: Денов туманидаги “Мармар” МЧЖ томонидан амалга оширилаётган лойиҳани муддатида ишга тушишини таъминлаш мақсадида кредит маблағлари ажратилишини таъминлаш. | E15: 45112 | F15: Билдирги | G15: ТИФ Миллий банк (Жумаев) | H15: Ш.Жўраев | I15: Бажарилган | M15: Январ | N15: Мажмуалар | O15: =+O14+1 -> 13 | P15: =+O15-A15 -> 0 | T15: =+J15 -> 0
A16: 14 | B16: 44922 | C16: Шеробод тумани Зарабоғ қишлоғи | D16: Шеробод туманидаги "Туз кони" имкониятларидан самарали фойдаланиш мақсадида даволаш бўйича туристларни жалб қилиш лойиҳасини ишлаб чиқиш. | E16: 44936 | G16: Вилоят ҳокимининг ўринбосарлари А.Орипов, Ж.Тўраев | H16: Ш.Жўраев | I16: Бажарилган | M16: Январ | N16: Мажмуалар | O16: =+O15+1 -> 14 | P16: =+O16-A16 -> 0 | T16: =+J16 -> 0
A17: 15 | B17: 44922 | C17: Термиз шаҳар | D17: Термиз шаҳар кичик саноат зонасидаги ички йўлларни таъмирлаш. | E17: 44985 | G17: "Сурхондарёавтойўл" корхонаси (У.Темиров) | H17: Ш.Жўраев | I17: Бажарилган | M17: Январ | N17: Мажмуалар | O17: =+O16+1 -> 15 | P17: =+O17-A17 -> 0 | T17: =+J17 -> 0
A18: 16 | B18: 44922 | C18: Термиз шаҳар | D18: Термиз шаҳридаги "Ал-Хоразмий ахборот технологиялари "ИТ" мактаби" нодавлат таълим муассасаси ташкил этиш учун кредит ажратилиши масаласини ҳал этиш. | E18: 45017 | F18: Билдирги | G18: Вилоят ҳокимининг ўринбосарлари А.Орипов Марказий банк бош бошқармаси (А.Тўхтаев) | H18: Ш.Жўраев | I18: Бажарилган | M18: Январ | N18: Мажмуалар | O18: =+O17+1 -> 16 | P18: =+O18-A18 -> 0 | T18: =+J18 -> 0
A19: 17 | B19: 44922 | C19: Термиз шаҳри | D19: Реновацияга тушган биноларни таъмирлаш масаласида қурилиш пудрат корхоналари раҳбарлари билан учрашиш ва инвесторларни аниқлаш. | E19: 45127 | F19: Билдирги | G19: Термиз шаҳар ҳокими Ў.Тўраев | H19: А.Амиров | I19: Бажарилган | J19: Термиз Тезкор Қурилиш МЧЖга "Тупроққўрғон" мфй Дилнаво кўчасидан 1,16 га ер майдони ажратилган | M19: Январ | N19: Мажмуалар | O19: =+O18+1 -> 17 | P19: =+O19-A19 -> 0 | Q19: 45066 | T19: =+J19 -> Термиз Тезкор Қурилиш МЧЖга "Тупроққўрғон" мфй Дилнаво кўчасидан 1,16 га ер майдони ажратилган
A20: 18 | B20: 44922 | C20: Термиз шаҳри | D20: Термиз шаҳри “Гулистон” маҳалласи Янги Ўзбекистон кўчасида асфальт ётқизиш, кўча ёритиш чироқлари ўрнатиш, йўл бўйлаб дарахт кўчатлари экиш, яшил ҳудудларни ташкил этиш ҳамда сувлаш тизимларини ўрнатиш ишларини якунлаш | E20: 44931 | G20: Вилоят Автомобиль йўлларидан фойдаланиш унитар корхонаси | H20: А.Амиров | I20: Бажарилган | M20: Январ | N20: Мажмуалар | O20: =+O19+1 -> 18 | P20: =+O20-A20 -> 0 | T20: =+J20 -> 0
A21: 19 | B21: 44922 | C21: Термиз шаҳри | D21: Термиз шаҳри “Гулистон” маҳалласи Янги Ўзбекистон кўчасида олиб борилаётган қурилиш ишларини назорат қилиш | E21: 45174 | F21: Доимий | G21: Сурхондарё вилоят Ҳудудий назорат инспекцияси (ГАСН) Б.Назаров | H21: А.Амиров | I21: Бажарилган | M21: Январ | N21: Мажмуалар | O21: =+O20+1 -> 19 | P21: =+O21-A21 -> 0 | T21: =+J21 -> 0
A22: 20 | B22: 44922 | C22: Термиз шаҳри | D22: Термиз шаҳри Ибн Сино кўчасидаги сифатсиз қурилган саломатлик йўлагини қурилиши бўйича текширув ўтказиш, йўлакни бузиш ва қайтадан сифатли қуриш | E22: 45078 | F22: Билдирги | G22: Термиз шаҳар ҳокими Ў.Тўраев | H22: А.Амиров | I22: Бажарилган | M22: Январ | N22: Мажмуалар | O22: =+O21+1 -> 20 | P22: =+O22-A22 -> 0 | Q22: 45066 | T22: =+J22 -> 0
A23: 21 | B23: 44922 | C23: Термиз шаҳри | D23: Термиз шаҳридаги 16-сонли мактабда биносини таъмирлаш бўйича лойиҳа-смета ҳужжатларини ишлаб чиқиш | E23: 44936 | G23: Термиз шаҳар ҳокими Ў.Тўраев | H23: А.Амиров | I23: Бажарилган | M23: Январ | N23: Мажмуалар | O23: =+O22+1 -> 21 | P23: =+O23-A23 -> 0 | T23: =+J23 -> 0
A24: 22 | B24: 44922 | C24: Термиз шаҳри | D24: “Юбилейний” бозоридаги мавжуд ҳолатни ўрганиш бўйича ишчи гуруҳ тузиш, 2023 йил 20 январга қадар сотувчиларнинг ҳар бири билан гаплашиб, уларни кўчириш | E24: 44946 | G24: Вилоят ҳокимининг ўринбосари А.Хидиров, Термиз шаҳар ҳокими Ў.Тўраев | H24: А.Амиров | I24: Бажарилган | M24: Январ | N24: Мажмуалар | O24: =+O23+1 -> 22 | P24: =+O24-A24 -> 0 | T24: =+J24 -> 0
A25: 23 | B25: 44922 | C25: Термиз шаҳри | D25: “Юбилейний” бозори ҳудудида ўтувчи тунеллни таъмирлаш бўйича лойиҳа хужжатларини кайта куриб чикиш ва курилиш ишларини бошлаш. | E25: 44931 | G25: Вилоят ҳокимининг ўринбосари А.Хидиров, Вилоят Автомобиль йўлларидан фойдаланиш унитар корхонаси Термиз шаҳар ҳокими Ў.Тўраев | H25: А.Амиров | I25: Бажарилган | M25: Январ | N25: Мажмуалар | O25: =+O24+1 -> 23 | P25: =+O25-A25 -> 0 | T25: =+J25 -> 0
A26: 24 | B26: 44922 | C26: Термиз шаҳри | D26: Термиз шаҳри “Паттакесар” маҳалласи Нурли келажак кўчасидаги йўл таъмири лойиҳасини қайта кўриб чиқиш | E26: 44931 | G26: Вилоят ҳокимининг ўринбосари А.Хидиров, Термиз шаҳар ҳокими Ў.Тўраев | H26: А.Амиров | I26: Бажарилган | M26: Январ | N26: Мажмуалар | O26: =+O25+1 -> 24 | P26: =+O26-A26 -> 0 | T26: =+J26 -> 0
A27: 25 | B27: 44922 | C27: Термиз шаҳри | D27: Термиз шаҳри “Паттакесар” маҳалласи ҳудудидаги икки қаватли уйларни таъмирлаш бўйича штаб фаолиятини йўлга қўйиш | E27: 44931 | G27: Панжи Қобилов, Шахар ИИБ | H27: А.Амиров | I27: Бажарилган | M27: Январ | N27: Мажмуалар | O27: =+O26+1 -> 25 | P27: =+O27-A27 -> 0 | T27: =+J27 -> 0
A28: 26 | B28: 44922 | C28: Термиз шаҳри | D28: Термиз шаҳри “Паттакесар” маҳалласи ҳудудидаги икки қаватли уйларни том ва фасад қисмини таъмирлаш, болалар майдончаси, автотураргоҳ ташкил этиш, ободонлаштириш ишларини олиб бориш ва чиқиндиларни олиб чиқиш | E28: 44954 | F28: Билдирги | G28: Панжи Қобилов, Шахар ИИБ | H28: А.Амиров | I28: Бажарилган | M28: Январ | N28: Мажмуалар | O28: =+O27+1 -> 26 | P28: =+O28-A28 -> 0 | T28: =+J28 -> 0
A29: 27 | B29: 44922 | C29: Термиз шаҳри | D29: Термиз шаҳри “Паттакесар” маҳалласи ҳудудида қурилаётган арзон уйларни фойдаланишга топшириш | E29: 44986 | F29: Билдирги | G29: Вилоят Халқ қабулхонаси А.Эшмуродов Термиз шаҳар ҳокими Ў.Тўраев | H29: А.Амиров | I29: Бажарилган | M29: Январ | N29: Мажмуалар | O29: =+O28+1 -> 27 | P29: =+O29-A29 -> 0 | T29: =+J29 -> 0
A30: 28 | B30: 44922 | C30: Термиз шаҳри | D30: “Сурхон Саноат Қурилиш” компанияси томонидан Фаровон массивида қурилиши белгиланган кўп қаватли уй-жойлар лойиҳасида янги мактаб, мактабгача таълим ташкилоти ва бошқа ижтимоий объектларни лойиҳалаш ишлари ишлаб чиқиш | E30: 44923 | G30: Вилоят курилиш бош бошкармаси К.Эшматов Термиз шаҳар ҳокими Ў.Тўраев | H30: А.Амиров | I30: Бажарилган | M30: Январ | N30: Мажмуалар | O30: =+O29+1 -> 28 | P30: =+O30-A30 -> 0 | T30: =+J30 -> 0
A31: 29 | B31: 44922 | C31: Термиз шаҳри | D31: Термиз эркин иқтисодий зонасини электр энергияси билан таъминлаш лойиҳасини якунлаш бўйича тармоқ жадвалини ишлаб чиқиш. | E31: 44925 | G31: “Сурхондарё ҲЭТК” АЖ (М.Шамсиддинов) | H31: А.Амиров | I31: Бажарилган | M31: Январ | N31: Мажмуалар | O31: =+O30+1 -> 29 | P31: =+O31-A31 -> 0 | T31: =+J31 -> 0
A32: 30 | B32: 44922 | C32: Мажмуа ва ташкилотлар билан муаммоли масалалар юзасидан йиғилиш | D32: Хоразм вилояти тажрибасидан келиб чиқиб, вилоятдаги долзарб муаммоларни ҳал этиш чора-тадбирлар дастурини ишлаб чиқиш. | E32: 44925 | G32: “Сурхондарё сув таъминот” тизимдаги ходимларнинг иш ҳақи бўйича мавжуд қарздорликларни бир кун муддатда тўлиқ бартараф этиш. | H32: А.Амиров | I32: Бажарилган | M32: Январ | N32: Мажмуалар | O32: =+O31+1 -> 30 | P32: =+O32-A32 -> 0 | T32: =+J32 -> 0
A33: 31 | B33: 44922 | C33: Мажмуа ва ташкилотлар билан муаммоли масалалар юзасидан йиғилиш | D33: Вилоятдаги буюртмачи ва назорат қилувчи ташкилотларнинг техник назорат ходимларини жалб қилиб, 2022 йилда инвестиция дастури, “Обод қишлоқ”, “Обод маҳалла” ва бошқа мақсадли дастурлар доирасида амалга оширилган қурилиш таъмирлаш ишлари сифатини кўриб чиқиб, мавжуд камчиликларни бартараф этиш чоралари белгилаш. | E33: 44936 | G33: Вилоят ҳокимининг ўринбосари А.Хидиров, алоқадор ташкилот ва корхоналар, Термиз шаҳар ва туманлар ҳокимликлари | H33: А.Амиров | I33: Бажарилган | M33: Январ | N33: Мажмуалар | O33: =+O32+1 -> 31 | P33: =+O33-A33 -> 0 | T33: =+J33 -> 0
A34: 32 | B34: 44922 | C34: Мажмуа ва ташкилотлар билан муаммоли масалалар юзасидан йиғилиш | D34: Термиз шаҳар ва Термиз тумани марказий автомобиль йўллари атрофларига манзарали кўчатларни экиш бўйича таклифлар ишлаб чиқиш. | E34: 44936 | G34: Вилоят ҳокимининг ўринбосари А.Хидиров, “Сурхондарёавтойўл” (У.Темиров) Термиз шаҳар ва туманлар ҳокимлари | H34: А.Амиров | I34: Бажарилган | M34: Январ | N34: Мажмуалар | O34: =+O33+1 -> 32 | P34: =+O34-A34 -> 0 | T34: =+J34 -> 0
A35: 33 | B35: 44922 | C35: Мажмуа ва ташкилотлар билан муаммоли масалалар юзасидан йиғилиш | D35: Аҳоли учун қўлай ва зарур коммуникациялар мавжуд бўлган ҳудудларда кўп қаватли уй-жойларни қуриш таклифларни ишлаб чиқиш. | E35: 44936 | G35: Вилоят Қурилиш бошқармаси (К.Эшматов), Термиз шаҳар ва туманлар ҳокимлари | H35: А.Амиров | I35: Бажарилган | M35: Январ | N35: Мажмуалар | O35: =+O34+1 -> 33 | P35: =+O35-A35 -> 0 | T35: =+J35 -> 0
A36: 34 | B36: 44922 | C36: Мажмуа ва ташкилотлар билан муаммоли масалалар юзасидан йиғилиш | D36: “Яшил макон” дастури доирасида кўп йиллик дарахт кўчатларини экиш, суғориш тизимини ташкил этиш. Вилоятдаги мавжуд кўп йиллик дарахтларни инвентаризациядан ўтказиб, уларни сақлаш учун далолатномалар асосида жойлардаги маҳаллалар раислари ва тегишли ташкилотлар ва корхоналарга топшириш. | E36: 45170 | F36: Билдирги | G36: Термиз шаҳар ва туманлар ҳокимликлари, Вилоят Экология ва атроф-муҳитни муҳофаза қилиш бошқармаси (Р.Сафарова) | H36: А.Амиров | I36: Бажарилган | M36: Январ | N36: Мажмуалар | O36: =+O35+1 -> 34 | P36: =+O36-A36 -> 0 | T36: =+J36 -> 0
A37: 35 | B37: 44922 | C37: Мажмуа ва ташкилотлар билан муаммоли масалалар юзасидан йиғилиш | D37: Вилоятдаги инвестиция дастури доирасида ижтимоий соҳа объектларини таъмирлаш ва реконструкция қилиш ишларини сифатини ўрнатилган тартибда кўриб чиқсин. | E37: 45044 | G37: Вилоят прокуратураси (келишув асосида) | H37: А.Амиров | I37: Бажарилган | M37: Январ | N37: Мажмуалар | O37: =+O36+1 -> 35 | P37: =+O37-A37 -> 0 | T37: =+J37 -> 0
A38: 36 | B38: 44922 | C38: Мажмуа ва ташкилотлар билан муаммоли масалалар юзасидан йиғилиш | D38: Вилоятдаги автомобиль йўлларини аҳволи ва уларни таъмирлаш ва реконструкция қилиш бўйича таклифларни ишлаб чиқиш. Бунда, автомобиль йўллар атрофларига кўп дарахтларни экишни назарда тутиш. | E38: 44931 | G38: “Сурхондарёавтойўл” ҳудудий йўллардан фойдаланиш ташкилоти (У.Темиров): | H38: А.Амиров | I38: Бажарилган | M38: Январ | N38: Мажмуалар | O38: =+O37+1 -> 36 | P38: =+O38-A38 -> 0 | T38: =+J38 -> 0
A39: 37 | B39: 44922 | C39: Мажмуа ва ташкилотлар билан муаммоли масалалар юзасидан йиғилиш | D39: Термиз ҳалқаро аэропортидан Термиз шаҳри ҳудудига қадар автомобиль йўллари атрофлари ободонлаштириш ва кўп йиллик дарахтларни экиш. | E39: 44984 | F39: Билдирги | G39: Термиз туман ҳокими Ш.Назаров, “Йўл кўкалам” ДУК (Б.Абраев) | H39: Термиз тумани | I39: Бажарилган | M39: Январ | N39: туманлар | O39: =+O38+1 -> 37 | P39: =+O39-A39 -> 0 | T39: =+J39 -> 0
A40: 38 | B40: 44922 | C40: Мажмуа ва ташкилотлар билан муаммоли масалалар юзасидан йиғилиш | D40: “Сурхондарё сув таъминот” тизимдаги ходимларнинг иш ҳақи бўйича мавжуд қарздорликларни бир кун муддатда тўлиқ бартараф этиш. | E40: 44931 | G40: “Сурхондарё сув таъминот” МЧЖ (Х.Сафоев) | H40: А.Амиров | I40: Бажарилган | M40: Январ | N40: Мажмуалар | O40: =+O39+1 -> 38 | P40: =+O40-A40 -> 0 | T40: =+J40 -> 0
...

Sheet Свод умумий-2
A1: Вилоят ҳокими У.Қосимов томонидан ҳудудларни ўрганиш давомида аниқланган муаммоларни бартараф этиш бўйича берилаётган тезкор топшириқларнинг ижроси тўғрисида МАЪЛУМОТ
I2: =+E7+F7 -> 188
E4: 10.11.2025 йил ҳолатига
A5: Т\Р | B5: Масъуллар | C5: Жами топшириқ сони | D5: Шундан
D6: Бажарилган | E6: Бажарилмаган | F6: Бажарилмоқда | V6: Бажарилган | W6: Бажарилмаган | X6: Бажарилмоқда
A7: ЖАМИ | C7: =+C8+C27 -> 4929 | D7: =+D8+D27 -> 4741 | E7: =+E8+E27 -> 136 | F7: =+F8+F27 -> 52 | U7: =+A7 -> ЖАМИ | V7: =+D7/C7 -> 0.96185839 | W7: =+E7/C7 -> 0.027591804 | X7: =+F7/C7 -> 0.010549807
A8: ЖАМИ (Мажмуалар) | C8: =SUM(C9:C26) -> 3482 | D8: =SUM(D9:D26) -> 3370 | E8: =SUM(E9:E26) -> 68 | F8: =SUM(F9:F26) -> 44 | U8: =+A8 -> ЖАМИ (Мажмуалар) | V8: =+D8/C8 -> 0.96783458 | W8: =+E8/C8 -> 0.019529006 | X8: =+F8/C8 -> 0.012636416
A9: 1 | B9: Ш.Ражабов | C9: =+D9+E9+F9 -> 565 | D9: =+COUNTIFS('Жами топшириқлар-1'!$H$3:$H$5027,B9,'Жами топшириқлар-1'!$I$3:$I$5027,$D$6) -> 554 | E9: =+COUNTIFS('Жами топшириқлар-1'!$H$3:$H$5027,B9,'Жами топшириқлар-1'!$I$3:$I$5027,$E$6) -> 7 | F9: =+COUNTIFS('Жами топшириқлар-1'!$H$3:$H$5027,B9,'Жами топшириқлар-1'!$I$3:$I$5027,$F$6) -> 4 | I9: Иқтисод | T9: =+A9 -> 1 | U9: =+B9 -> Ш.Ражабов | V9: =+D9/C9 -> 0.98053097 | W9: =+E9/C9 -> 0.012389381 | X9: =+F9/C9 -> 0.007079646
A10: 2 | B10: А.Амиров | C10: =+D10+E10+F10 -> 972 | D10: =+COUNTIFS('Жами топшириқлар-1'!$H$3:$H$5027,B10,'Жами топшириқлар-1'!$I$3:$I$5027,$D$6) -> 927 | E10: =+COUNTIFS('Жами топшириқлар-1'!$H$3:$H$5027,B10,'Жами топшириқлар-1'!$I$3:$I$5027,$E$6) -> 20 | F10: =+COUNTIFS('Жами топшириқлар-1'!$H$3:$H$5027,B10,'Жами топшириқлар-1'!$I$3:$I$5027,$F$6) -> 25 | I10: Қурилиш | T10: =+A10 -> 2 | U10: =+B10 -> А.Амиров | V10: =+D10/C10 -> 0.9537037 | W10: =+E10/C10 -> 0.020576132 | X10: =+F10/C10 -> 0.025720165
A11: 3 | B11: Ш.Жўраев | C11: =+D11+E11+F11 -> 209 | D11: =+COUNTIFS('Жами топшириқлар-1'!$H$3:$H$5027,B11,'Жами топшириқлар-1'!$I$3:$I$5027,$D$6) -> 205 | E11: =+COUNTIFS('Жами топшириқлар-1'!$H$3:$H$5027,B11,'Жами топшириқлар-1'!$I$3:$I$5027,$E$6) -> 4 | F11: =+COUNTIFS('Жами топшириқлар-1'!$H$3:$H$5027,B11,'Жами топшириқлар-1'!$I$3:$I$5027,$F$6) -> 0 | I11: Инвестиция | T11: =+A11 -> 3 | U11: =+B11 -> Ш.Жўраев | V11: =+D11/C11 -> 0.98086124 | W11: =+E11/C11 -> 0.019138756 | X11: =+F11/C11 -> 0
A12: 4 | B12: Ф.Исмоилов | C12: =+D12+E12+F12 -> 386 | D12: =+COUNTIFS('Жами топшириқлар-1'!$H$3:$H$5027,B12,'Жами топшириқлар-1'!$I$3:$I$5027,$D$6) -> 382 | E12: =+COUNTIFS('Жами топшириқлар-1'!$H$3:$H$5027,B12,'Жами топшириқлар-1'!$I$3:$I$5027,$E$6) -> 2 | F12: =+COUNTIFS('Жами топшириқлар-1'!$H$3:$H$5027,B12,'Жами топшириқлар-1'!$I$3:$I$5027,$F$6) -> 2 | I12: Қишлоқ хўжалиги | T12: =+A12 -> 4 | U12: =+B12 -> Ф.Исмоилов | V12: =+D12/C12 -> 0.98963731 | W12: =+E12/C12 -> 0.0051813472 | X12: =+F12/C12 -> 0.0051813472
A13: 5 | B13: И.Сапаров | C13: =+D13+E13+F13 -> 628 | D13: =+COUNTIFS('Жами топшириқлар-1'!$H$3:$H$5027,B13,'Жами топшириқлар-1'!$I$3:$I$5027,$D$6) -> 599 | E13: =+COUNTIFS('Жами топшириқлар-1'!$H$3:$H$5027,B13,'Жами топшириқлар-1'!$I$3:$I$5027,$E$6) -> 22 | F13: =+COUNTIFS('Жами топшириқлар-1'!$H$3:$H$5027,B13,'Жами топшириқлар-1'!$I$3:$I$5027,$F$6) -> 7 | I13: Ёшлар ва ижтимоий | T13: =+A13 -> 5 | U13: =+B13 -> И.Сапаров | V13: =+D13/C13 -> 0.95382166 | W13: =+E13/C13 -> 0.035031847 | X13: =+F13/C13 -> 0.011146497
A14: 6 | B14: Ж.Тўраев | C14: =+D14+E14+F14 -> 183 | D14: =+COUNTIFS('Жами топшириқлар-1'!$H$3:$H$5027,B14,'Жами топшириқлар-1'!$I$3:$I$5027,$D$6) -> 172 | E14: =+COUNTIFS('Жами топшириқлар-1'!$H$3:$H$5027,B14,'Жами топшириқлар-1'!$I$3:$I$5027,$E$6) -> 10 | F14: =+COUNTIFS('Жами топшириқлар-1'!$H$3:$H$5027,B14,'Жами топшириқлар-1'!$I$3:$I$5027,$F$6) -> 1 | I14: Туризм ва спорт | T14: =+A14 -> 6 | U14: =+B14 -> Ж.Тўраев | V14: =+D14/C14 -> 0.93989071 | W14: =+E14/C14 -> 0.054644809 | X14: =+F14/C14 -> 0.0054644809
A15: 7 | B15: А.Абдурахмонов | C15: =+D15+E15+F15 -> 14 | D15: =+COUNTIFS('Жами топшириқлар-1'!$H$3:$H$5027,B15,'Жами топшириқлар-1'!$I$3:$I$5027,$D$6) -> 14 | E15: =+COUNTIFS('Жами топшириқлар-1'!$H$3:$H$5027,B15,'Жами топшириқлар-1'!$I$3:$I$5027,$E$6) -> 0 | F15: =+COUNTIFS('Жами топшириқлар-1'!$H$3:$H$5027,B15,'Жами топшириқлар-1'!$I$3:$I$5027,$F$6) -> 0 | I15: Жамоат ва диний | T15: =+A15 -> 7 | U15: =+B15 -> А.Абдурахмонов | V15: =+D15/C15 -> 1 | W15: =+E15/C15 -> 0 | X15: =+F15/C15 -> 0
A16: 8 | B16: З.Хидирова | C16: =+D16+E16+F16 -> 55 | D16: =+COUNTIFS('Жами топшириқлар-1'!$H$3:$H$5027,B16,'Жами топшириқлар-1'!$I$3:$I$5027,$D$6) -> 54 | E16: =+COUNTIFS('Жами топшириқлар-1'!$H$3:$H$5027,B16,'Жами топшириқлар-1'!$I$3:$I$5027,$E$6) -> 1 | F16: =+COUNTIFS('Жами топшириқлар-1'!$H$3:$H$5027,B16,'Жами топшириқлар-1'!$I$3:$I$5027,$F$6) -> 0 | I16: Махалла ва оила | T16: =+A16 -> 8 | U16: =+B16 -> З.Хидирова | V16: =+D16/C16 -> 0.98181818 | W16: =+E16/C16 -> 0.018181818 | X16: =+F16/C16 -> 0
A17: 9 | B17: Ф.Менглиев | C17: =+D17+E17+F17 -> 171 | D17: =+COUNTIFS('Жами топшириқлар-1'!$H$3:$H$5027,B17,'Жами топшириқлар-1'!$I$3:$I$5027,$D$6) -> 171 | E17: =+COUNTIFS('Жами топшириқлар-1'!$H$3:$H$5027,B17,'Жами топшириқлар-1'!$I$3:$I$5027,$E$6) -> 0 | F17: =+COUNTIFS('Жами топшириқлар-1'!$H$3:$H$5027,B17,'Жами топшириқлар-1'!$I$3:$I$5027,$F$6) -> 0 | I17: Вил Кадр | T17: =+A17 -> 9 | U17: =+B17 -> Ф.Менглиев | V17: =+D17/C17 -> 1 | W17: =+E17/C17 -> 0 | X17: =+F17/C17 -> 0
A18: 10 | B18: Ф.Очилдиев | C18: =+D18+E18+F18 -> 10 | D18: =+COUNTIFS('Жами топшириқлар-1'!$H$3:$H$5027,B18,'Жами топшириқлар-1'!$I$3:$I$5027,$D$6) -> 9 | E18: =+COUNTIFS('Жами топшириқлар-1'!$H$3:$H$5027,B18,'Жами топшириқлар-1'!$I$3:$I$5027,$E$6) -> 0 | F18: =+COUNTIFS('Жами топшириқлар-1'!$H$3:$H$5027,B18,'Жами топшириқлар-1'!$I$3:$I$5027,$F$6) -> 1 | I18: Ахборот тахлил | T18: =+A18 -> 10 | U18: =+B18 -> Ф.Очилдиев | V18: =+D18/C18 -> 0.9 | W18: =+E18/C18 -> 0 | X18: =+F18/C18 -> 0.1
A19: 11 | B19: З.Назаров | C19: =+D19+E19+F19 -> 186 | D19: =+COUNTIFS('Жами топшириқлар-1'!$H$3:$H$5027,B19,'Жами топшириқлар-1'!$I$3:$I$5027,$D$6) -> 184 | E19: =+COUNTIFS('Жами топшириқлар-1'!$H$3:$H$5027,B19,'Жами топшириқлар-1'!$I$3:$I$5027,$E$6) -> 2 | F19: =+COUNTIFS('Жами топшириқлар-1'!$H$3:$H$5027,B19,'Жами топшириқлар-1'!$I$3:$I$5027,$F$6) -> 0 | I19: Харбий гурух | T19: =+A19 -> 11 | U19: =+B19 -> З.Назаров | V19: =+D19/C19 -> 0.98924731 | W19: =+E19/C19 -> 0.010752688 | X19: =+F19/C19 -> 0
A20: 12 | B20: О.Ашуров | C20: =+D20+E20+F20 -> 9 | D20: =+COUNTIFS('Жами топшириқлар-1'!$H$3:$H$5027,B20,'Жами топшириқлар-1'!$I$3:$I$5027,$D$6) -> 9 | E20: =+COUNTIFS('Жами топшириқлар-1'!$H$3:$H$5027,B20,'Жами топшириқлар-1'!$I$3:$I$5027,$E$6) -> 0 | F20: =+COUNTIFS('Жами топшириқлар-1'!$H$3:$H$5027,B20,'Жами топшириқлар-1'!$I$3:$I$5027,$F$6) -> 0 | T20: =+A20 -> 12 | U20: =+B20 -> О.Ашуров | V20: =+D20/C20 -> 1 | W20: =+E20/C20 -> 0 | X20: =+F20/C20 -> 0
A21: 13 | B21: М.Давлатов | C21: =+D21+E21+F21 -> 27 | D21: =+COUNTIFS('Жами топшириқлар-1'!$H$3:$H$5027,B21,'Жами топшириқлар-1'!$I$3:$I$5027,$D$6) -> 27 | E21: =+COUNTIFS('Жами топшириқлар-1'!$H$3:$H$5027,B21,'Жами топшириқлар-1'!$I$3:$I$5027,$E$6) -> 0 | F21: =+COUNTIFS('Жами топшириқлар-1'!$H$3:$H$5027,B21,'Жами топшириқлар-1'!$I$3:$I$5027,$F$6) -> 0 | T21: =+A21 -> 13 | U21: =+B21 -> М.Давлатов | V21: =+D21/C21 -> 1 | W21: =+E21/C21 -> 0 | X21: =+F21/C21 -> 0
A22: 14 | B22: Д.Бобоёров | C22: =+D22+E22+F22 -> 1 | D22: =+COUNTIFS('Жами топшириқлар-1'!$H$3:$H$5027,B22,'Жами топшириқлар-1'!$I$3:$I$5027,$D$6) -> 1 | E22: =+COUNTIFS('Жами топшириқлар-1'!$H$3:$H$5027,B22,'Жами топшириқлар-1'!$I$3:$I$5027,$E$6) -> 0 | F22: =+COUNTIFS('Жами топшириқлар-1'!$H$3:$H$5027,B22,'Жами топшириқлар-1'!$I$3:$I$5027,$F$6) -> 0 | T22: =+A22 -> 14 | U22: =+B22 -> Д.Бобоёров | V22: =+D22/C22 -> 1 | W22: =+E22/C22 -> 0 | X22: =+F22/C22 -> 0
A23: 15 | B23: Б.Дониёров | C23: =+D23+E23+F23 -> 66 | D23: =+COUNTIFS('Жами топшириқлар-1'!$H$3:$H$5027,B23,'Жами топшириқлар-1'!$I$3:$I$5027,$D$6) -> 62 | E23: =+COUNTIFS('Жами топшириқлар-1'!$H$3:$H$5027,B23,'Жами топшириқлар-1'!$I$3:$I$5027,$E$6) -> 0 | F23: =+COUNTIFS('Жами топшириқлар-1'!$H$3:$H$5027,B23,'Жами топшириқлар-1'!$I$3:$I$5027,$F$6) -> 4 | I23: Мурожаатлар | T23: =+A23 -> 15 | U23: =+B23 -> Б.Дониёров | V23: =+D23/C23 -> 0.93939394 | W23: =+E23/C23 -> 0 | X23: =+F23/C23 -> 0.060606061
A24: 16 | B24: Б.Бабаджанов Прокуратура (2-сектор) | C24: =+D24+E24+F24 -> 0 | D24: =+COUNTIFS('Жами топшириқлар-1'!$H$3:$H$5027,B24,'Жами топшириқлар-1'!$I$3:$I$5027,$D$6) -> 0 | E24: =+COUNTIFS('Жами топшириқлар-1'!$H$3:$H$5027,B24,'Жами топшириқлар-1'!$I$3:$I$5027,$E$6) -> 0 | F24: =+COUNTIFS('Жами топшириқлар-1'!$H$3:$H$5027,B24,'Жами топшириқлар-1'!$I$3:$I$5027,$F$6) -> 0 | I24: Вилоят, шаҳар ва туман прокурорлари | T24: =+A24 -> 16 | U24: =+B24 -> Б.Бабаджанов Прокуратура (2-сектор)
A25: 17 | B25: Т.Исмаилов ИИБ (3-сектор) | C25: =+D25+E25+F25 -> 0 | D25: =+COUNTIFS('Жами топшириқлар-1'!$H$3:$H$5027,B25,'Жами топшириқлар-1'!$I$3:$I$5027,$D$6) -> 0 | E25: =+COUNTIFS('Жами топшириқлар-1'!$H$3:$H$5027,B25,'Жами топшириқлар-1'!$I$3:$I$5027,$E$6) -> 0 | F25: =+COUNTIFS('Жами топшириқлар-1'!$H$3:$H$5027,B25,'Жами топшириқлар-1'!$I$3:$I$5027,$F$6) -> 0 | I25: Вилоят, шаҳар ва туман ИИБ бошлиқлари | T25: =+A25 -> 17 | U25: =+B25 -> Т.Исмаилов ИИБ (3-сектор)
A26: 18 | B26: Э.Нарманов Солиқ (4-сектор) | C26: =+D26+E26+F26 -> 0 | D26: =+COUNTIFS('Жами топшириқлар-1'!$H$3:$H$5027,B26,'Жами топшириқлар-1'!$I$3:$I$5027,$D$6) -> 0 | E26: =+COUNTIFS('Жами топшириқлар-1'!$H$3:$H$5027,B26,'Жами топшириқлар-1'!$I$3:$I$5027,$E$6) -> 0 | F26: =+COUNTIFS('Жами топшириқлар-1'!$H$3:$H$5027,B26,'Жами топшириқлар-1'!$I$3:$I$5027,$F$6) -> 0 | I26: Вилоят, шаҳар ва туман Солиқ бошлиқлари | T26: =+A26 -> 18 | U26: =+B26 -> Э.Нарманов Солиқ (4-сектор) | V26: =+D26/C26 -> #DIV/0! | W26: =+E26/C26 -> #DIV/0! | X26: =+F26/C26 -> #DIV/0!
A27: ЖАМИ (Туманлар) | C27: =SUM(C28:C43) -> 1447 | D27: =SUM(D28:D43) -> 1371 | E27: =SUM(E28:E43) -> 68 | F27: =SUM(F28:F43) -> 8 | U27: =+A27 -> ЖАМИ (Туманлар) | V27: =+D27/C27 -> 0.94747754 | W27: =+E27/C27 -> 0.04699378 | X27: =+F27/C27 -> 0.00552868
A28: 1 | B28: Термиз шаҳар | C28: =+D28+E28+F28 -> 286 | D28: =+COUNTIFS('Жами топшириқлар-1'!$H$3:$H$5027,B28,'Жами топшириқлар-1'!$I$3:$I$5027,$D$6) -> 277 | E28: =+COUNTIFS('Жами топшириқлар-1'!$H$3:$H$5027,B28,'Жами топшириқлар-1'!$I$3:$I$5027,$E$6) -> 6 | F28: =+COUNTIFS('Жами топшириқлар-1'!$H$3:$H$5027,B28,'Жами топшириқлар-1'!$I$3:$I$5027,$F$6) -> 3 | T28: =+A28 -> 1 | U28: =+B28 -> Термиз шаҳар | V28: =+D28/C28 -> 0.96853147 | W28: =+E28/C28 -> 0.020979021 | X28: =+F28/C28 -> 0.01048951
A29: 2 | B29: Ангор тумани | C29: =+D29+E29+F29 -> 75 | D29: =+COUNTIFS('Жами топшириқлар-1'!$H$3:$H$5027,B29,'Жами топшириқлар-1'!$I$3:$I$5027,$D$6) -> 66 | E29: =+COUNTIFS('Жами топшириқлар-1'!$H$3:$H$5027,B29,'Жами топшириқлар-1'!$I$3:$I$5027,$E$6) -> 8 | F29: =+COUNTIFS('Жами топшириқлар-1'!$H$3:$H$5027,B29,'Жами топшириқлар-1'!$I$3:$I$5027,$F$6) -> 1 | T29: =+A29 -> 2 | U29: =+B29 -> Ангор тумани | V29: =+D29/C29 -> 0.88 | W29: =+E29/C29 -> 0.10666667 | X29: =+F29/C29 -> 0.013333333
A30: 3 | B30: Бандихон тумани | C30: =+D30+E30+F30 -> 52 | D30: =+COUNTIFS('Жами топшириқлар-1'!$H$3:$H$5027,B30,'Жами топшириқлар-1'!$I$3:$I$5027,$D$6) -> 40 | E30: =+COUNTIFS('Жами топшириқлар-1'!$H$3:$H$5027,B30,'Жами топшириқлар-1'!$I$3:$I$5027,$E$6) -> 12 | F30: =+COUNTIFS('Жами топшириқлар-1'!$H$3:$H$5027,B30,'Жами топшириқлар-1'!$I$3:$I$5027,$F$6) -> 0 | T30: =+A30 -> 3 | U30: =+B30 -> Бандихон тумани | V30: =+D30/C30 -> 0.76923077 | W30: =+E30/C30 -> 0.23076923 | X30: =+F30/C30 -> 0
A31: 4 | B31: Бойсун тумани | C31: =+D31+E31+F31 -> 47 | D31: =+COUNTIFS('Жами топшириқлар-1'!$H$3:$H$5027,B31,'Жами топшириқлар-1'!$I$3:$I$5027,$D$6) -> 42 | E31: =+COUNTIFS('Жами топшириқлар-1'!$H$3:$H$5027,B31,'Жами топшириқлар-1'!$I$3:$I$5027,$E$6) -> 5 | F31: =+COUNTIFS('Жами топшириқлар-1'!$H$3:$H$5027,B31,'Жами топшириқлар-1'!$I$3:$I$5027,$F$6) -> 0 | T31: =+A31 -> 4 | U31: =+B31 -> Бойсун тумани | V31: =+D31/C31 -> 0.89361702 | W31: =+E31/C31 -> 0.10638298 | X31: =+F31/C31 -> 0
A32: 5 | B32: Денов тумани | C32: =+D32+E32+F32 -> 151 | D32: =+COUNTIFS('Жами топшириқлар-1'!$H$3:$H$5027,B32,'Жами топшириқлар-1'!$I$3:$I$5027,$D$6) -> 146 | E32: =+COUNTIFS('Жами топшириқлар-1'!$H$3:$H$5027,B32,'Жами топшириқлар-1'!$I$3:$I$5027,$E$6) -> 5 | F32: =+COUNTIFS('Жами топшириқлар-1'!$H$3:$H$5027,B32,'Жами топшириқлар-1'!$I$3:$I$5027,$F$6) -> 0 | T32: =+A32 -> 5 | U32: =+B32 -> Денов тумани | V32: =+D32/C32 -> 0.96688742 | W32: =+E32/C32 -> 0.033112583 | X32: =+F32/C32 -> 0
A33: 6 | B33: Жарқурғон тумани | C33: =+D33+E33+F33 -> 89 | D33: =+COUNTIFS('Жами топшириқлар-1'!$H$3:$H$5027,B33,'Жами топшириқлар-1'!$I$3:$I$5027,$D$6) -> 86 | E33: =+COUNTIFS('Жами топшириқлар-1'!$H$3:$H$5027,B33,'Жами топшириқлар-1'!$I$3:$I$5027,$E$6) -> 3 | F33: =+COUNTIFS('Жами топшириқлар-1'!$H$3:$H$5027,B33,'Жами топшириқлар-1'!$I$3:$I$5027,$F$6) -> 0 | T33: =+A33 -> 6 | U33: =+B33 -> Жарқурғон тумани | V33: =+D33/C33 -> 0.96629213 | W33: =+E33/C33 -> 0.033707865 | X33: =+F33/C33 -> 0
A34: 7 | B34: Қизириқ тумани | C34: =+D34+E34+F34 -> 81 | D34: =+COUNTIFS('Жами топшириқлар-1'!$H$3:$H$5027,B34,'Жами топшириқлар-1'!$I$3:$I$5027,$D$6) -> 75 | E34: =+COUNTIFS('Жами топшириқлар-1'!$H$3:$H$5027,B34,'Жами топшириқлар-1'!$I$3:$I$5027,$E$6) -> 5 | F34: =+COUNTIFS('Жами топшириқлар-1'!$H$3:$H$5027,B34,'Жами топшириқлар-1'!$I$3:$I$5027,$F$6) -> 1 | T34: =+A34 -> 7 | U34: =+B34 -> Қизириқ тумани | V34: =+D34/C34 -> 0.92592593 | W34: =+E34/C34 -> 0.061728395 | X34: =+F34/C34 -> 0.012345679
A35: 8 | B35: Қумқўрғон тумани | C35: =+D35+E35+F35 -> 80 | D35: =+COUNTIFS('Жами топшириқлар-1'!$H$3:$H$5027,B35,'Жами топшириқлар-1'!$I$3:$I$5027,$D$6) -> 75 | E35: =+COUNTIFS('Жами топшириқлар-1'!$H$3:$H$5027,B35,'Жами топшириқлар-1'!$I$3:$I$5027,$E$6) -> 5 | F35: =+COUNTIFS('Жами топшириқлар-1'!$H$3:$H$5027,B35,'Жами топшириқлар-1'!$I$3:$I$5027,$F$6) -> 0 | T35: =+A35 -> 8 | U35: =+B35 -> Қумқўрғон тумани | V35: =+D35/C35 -> 0.9375 | W35: =+E35/C35 -> 0.0625 | X35: =+F35/C35 -> 0
A36: 9 | B36: Музработ тумани | C36: =+D36+E36+F36 -> 60 | D36: =+COUNTIFS('Жами топшириқлар-1'!$H$3:$H$5027,B36,'Жами топшириқлар-1'!$I$3:$I$5027,$D$6) -> 56 | E36: =+COUNTIFS('Жами топшириқлар-1'!$H$3:$H$5027,B36,'Жами топшириқлар-1'!$I$3:$I$5027,$E$6) -> 2 | F36: =+COUNTIFS('Жами топшириқлар-1'!$H$3:$H$5027,B36,'Жами топшириқлар-1'!$I$3:$I$5027,$F$6) -> 2 | T36: =+A36 -> 9 | U36: =+B36 -> Музработ тумани | V36: =+D36/C36 -> 0.93333333 | W36: =+E36/C36 -> 0.033333333 | X36: =+F36/C36 -> 0.033333333
A37: 10 | B37: Олтинсой тумани | C37: =+D37+E37+F37 -> 49 | D37: =+COUNTIFS('Жами топшириқлар-1'!$H$3:$H$5027,B37,'Жами топшириқлар-1'!$I$3:$I$5027,$D$6) -> 46 | E37: =+COUNTIFS('Жами топшириқлар-1'!$H$3:$H$5027,B37,'Жами топшириқлар-1'!$I$3:$I$5027,$E$6) -> 2 | F37: =+COUNTIFS('Жами топшириқлар-1'!$H$3:$H$5027,B37,'Жами топшириқлар-1'!$I$3:$I$5027,$F$6) -> 1 | T37: =+A37 -> 10 | U37: =+B37 -> Олтинсой тумани | V37: =+D37/C37 -> 0.93877551 | W37: =+E37/C37 -> 0.040816327 | X37: =+F37/C37 -> 0.020408163
A38: 11 | B38: Сариосиё тумани | C38: =+D38+E38+F38 -> 69 | D38: =+COUNTIFS('Жами топшириқлар-1'!$H$3:$H$5027,B38,'Жами топшириқлар-1'!$I$3:$I$5027,$D$6) -> 67 | E38: =+COUNTIFS('Жами топшириқлар-1'!$H$3:$H$5027,B38,'Жами топшириқлар-1'!$I$3:$I$5027,$E$6) -> 2 | F38: =+COUNTIFS('Жами топшириқлар-1'!$H$3:$H$5027,B38,'Жами топшириқлар-1'!$I$3:$I$5027,$F$6) -> 0 | T38: =+A38 -> 11 | U38: =+B38 -> Сариосиё тумани | V38: =+D38/C38 -> 0.97101449 | W38: =+E38/C38 -> 0.028985507 | X38: =+F38/C38 -> 0
A39: 12 | B39: Термиз тумани | C39: =+D39+E39+F39 -> 64 | D39: =+COUNTIFS('Жами топшириқлар-1'!$H$3:$H$5027,B39,'Жами топшириқлар-1'!$I$3:$I$5027,$D$6) -> 62 | E39: =+COUNTIFS('Жами топшириқлар-1'!$H$3:$H$5027,B39,'Жами топшириқлар-1'!$I$3:$I$5027,$E$6) -> 2 | F39: =+COUNTIFS('Жами топшириқлар-1'!$H$3:$H$5027,B39,'Жами топшириқлар-1'!$I$3:$I$5027,$F$6) -> 0 | T39: =+A39 -> 12 | U39: =+B39 -> Термиз тумани | V39: =+D39/C39 -> 0.96875 | W39: =+E39/C39 -> 0.03125 | X39: =+F39/C39 -> 0
... A42: 15 | B42: Шўрчи тумани | C42: =+D42+E42+F42 -> 91 | D42: =+COUNTIFS('Жами топшириқлар-1'!$H$3:$H$5027,B42,'Жами топшириқлар-1'!$I$3:$I$5027,$D$6) -> 86 | E42: =+COUNTIFS('Жами топшириқлар-1'!$H$3:$H$5027,B42,'Жами топшириқлар-1'!$I$3:$I$5027,$E$6) -> 5 | F42: =+COUNTIFS('Жами топшириқлар-1'!$H$3:$H$5027,B42,'Жами топшириқлар-1'!$I$3:$I$5027,$F$6) -> 0 | T42: =+A42 -> 15 | U42: =+B42 -> Шўрчи тумани | V42: =+D42/C42 -> 0.94505495 | W42: =+E42/C42 -> 0.054945055 | X42: =+F42/C42 -> 0
B43: Шаҳар ва туман ҳокимликлари | C43: =+D43+E43+F43 -> 133 | D43: =+COUNTIFS('Жами топшириқлар-1'!$H$3:$H$5027,B43,'Жами топшириқлар-1'!$I$3:$I$5027,$D$6) -> 133 | E43: =+COUNTIFS('Жами топшириқлар-1'!$H$3:$H$5027,B43,'Жами топшириқлар-1'!$I$3:$I$5027,$E$6) -> 0 | F43: =+COUNTIFS('Жами топшириқлар-1'!$H$3:$H$5027,B43,'Жами топшириқлар-1'!$I$3:$I$5027,$F$6) -> 0 | T43: =+A43 -> 0 | U43: =+B43 -> Шаҳар ва туман ҳокимликлари | V43: =+D43/C43 -> 1 | W43: =+E43/C43 -> 0 | X43: =+F43/C43 -> 0

Sheet Мажмуалар
A1: Вилоят ҳокими У.Қосимов томонидан ҳудудларни ўрганиш давомида аниқланган муаммоларни бартараф этиш бўйича берилаётган тезкор топшириқларнинг ижроси тўғрисида МАЪЛУМОТ
E4: 28.10.2025 йил ҳолатига
A5: Т\Р | B5: Масъуллар | C5: Жами топшириқ сони | D5: Шундан
D6: Бажарилган | E6: Бажарилмаган | F6: Бажарилмоқда | V6: Бажарилган | W6: Бажарилмаган | X6: Бажарилмоқда
A7: ЖАМИ (Мажмуалар) | C7: =SUM(C8:C25) -> 3482 | D7: =SUM(D8:D25) -> 3370 | E7: =SUM(E8:E25) -> 68 | F7: =SUM(F8:F25) -> 44 | U7: =+A7 -> ЖАМИ (Мажмуалар) | V7: =+D7/C7 -> 0.96783458 | W7: =+E7/C7 -> 0.019529006 | X7: =+F7/C7 -> 0.012636416
A8: 1 | B8: А.Амиров | C8: =+D8+E8+F8 -> 972 | D8: =+COUNTIFS('Жами топшириқлар-1'!$H$3:$H$5027,B8,'Жами топшириқлар-1'!$I$3:$I$5027,$D$6) -> 927 | E8: =+COUNTIFS('Жами топшириқлар-1'!$H$3:$H$5027,B8,'Жами топшириқлар-1'!$I$3:$I$5027,$E$6) -> 20 | F8: =+COUNTIFS('Жами топшириқлар-1'!$H$3:$H$5027,B8,'Жами топшириқлар-1'!$I$3:$I$5027,$F$6) -> 25 | I8: Қурилиш | T8: =+A8 -> 1 | U8: =+B8 -> А.Амиров | V8: =+D8/C8 -> 0.9537037 | W8: =+E8/C8 -> 0.020576132 | X8: =+F8/C8 -> 0.025720165
A9: 2 | B9: И.Сапаров | C9: =+D9+E9+F9 -> 628 | D9: =+COUNTIFS('Жами топшириқлар-1'!$H$3:$H$5027,B9,'Жами топшириқлар-1'!$I$3:$I$5027,$D$6) -> 599 | E9: =+COUNTIFS('Жами топшириқлар-1'!$H$3:$H$5027,B9,'Жами топшириқлар-1'!$I$3:$I$5027,$E$6) -> 22 | F9: =+COUNTIFS('Жами топшириқлар-1'!$H$3:$H$5027,B9,'Жами топшириқлар-1'!$I$3:$I$5027,$F$6) -> 7 | I9: Ёшлар ва ижтимоий | T9: =+A9 -> 2 | U9: =+B9 -> И.Сапаров | V9: =+D9/C9 -> 0.95382166 | W9: =+E9/C9 -> 0.035031847 | X9: =+F9/C9 -> 0.011146497
A10: 3 | B10: Ж.Тўраев | C10: =+D10+E10+F10 -> 183 | D10: =+COUNTIFS('Жами топшириқлар-1'!$H$3:$H$5027,B10,'Жами топшириқлар-1'!$I$3:$I$5027,$D$6) -> 172 | E10: =+COUNTIFS('Жами топшириқлар-1'!$H$3:$H$5027,B10,'Жами топшириқлар-1'!$I$3:$I$5027,$E$6) -> 10 | F10: =+COUNTIFS('Жами топшириқлар-1'!$H$3:$H$5027,B10,'Жами топшириқлар-1'!$I$3:$I$5027,$F$6) -> 1 | I10: Туризм ва спорт | T10: =+A10 -> 3 | U10: =+B10 -> Ж.Тўраев | V10: =+D10/C10 -> 0.93989071 | W10: =+E10/C10 -> 0.054644809 | X10: =+F10/C10 -> 0.0054644809
A11: 4 | B11: Ш.Ражабов | C11: =+D11+E11+F11 -> 565 | D11: =+COUNTIFS('Жами топшириқлар-1'!$H$3:$H$5027,B11,'Жами топшириқлар-1'!$I$3:$I$5027,$D$6) -> 554 | E11: =+COUNTIFS('Жами топшириқлар-1'!$H$3:$H$5027,B11,'Жами топшириқлар-1'!$I$3:$I$5027,$E$6) -> 7 | F11: =+COUNTIFS('Жами топшириқлар-1'!$H$3:$H$5027,B11,'Жами топшириқлар-1'!$I$3:$I$5027,$F$6) -> 4 | I11: Иқтисод | T11: =+A11 -> 4 | U11: =+B11 -> Ш.Ражабов | V11: =+D11/C11 -> 0.98053097 | W11: =+E11/C11 -> 0.012389381 | X11: =+F11/C11 -> 0.007079646
A12: 5 | B12: Ф.Исмоилов | C12: =+D12+E12+F12 -> 386 | D12: =+COUNTIFS('Жами топшириқлар-1'!$H$3:$H$5027,B12,'Жами топшириқлар-1'!$I$3:$I$5027,$D$6) -> 382 | E12: =+COUNTIFS('Жами топшириқлар-1'!$H$3:$H$5027,B12,'Жами топшириқлар-1'!$I$3:$I$5027,$E$6) -> 2 | F12: =+COUNTIFS('Жами топшириқлар-1'!$H$3:$H$5027,B12,'Жами топшириқлар-1'!$I$3:$I$5027,$F$6) -> 2 | I12: Қишлоқ хўжалиги | T12: =+A12 -> 5 | U12: =+B12 -> Ф.Исмоилов | V12: =+D12/C12 -> 0.98963731 | W12: =+E12/C12 -> 0.0051813472 | X12: =+F12/C12 -> 0.0051813472
A13: 6 | B13: Ш.Жўраев | C13: =+D13+E13+F13 -> 209 | D13: =+COUNTIFS('Жами топшириқлар-1'!$H$3:$H$5027,B13,'Жами топшириқлар-1'!$I$3:$I$5027,$D$6) -> 205 | E13: =+COUNTIFS('Жами топшириқлар-1'!$H$3:$H$5027,B13,'Жами топшириқлар-1'!$I$3:$I$5027,$E$6) -> 4 | F13: =+COUNTIFS('Жами топшириқлар-1'!$H$3:$H$5027,B13,'Жами топшириқлар-1'!$I$3:$I$5027,$F$6) -> 0 | I13: Инвестиция | T13: =+A13 -> 6 | U13: =+B13 -> Ш.Жўраев | V13: =+D13/C13 -> 0.98086124 | W13: =+E13/C13 -> 0.019138756 | X13: =+F13/C13 -> 0
A14: 7 | B14: Э.Нарманов Солиқ (4-сектор) | C14: =+D14+E14+F14 -> 0 | D14: =+COUNTIFS('Жами топшириқлар-1'!$H$3:$H$5027,B14,'Жами топшириқлар-1'!$I$3:$I$5027,$D$6) -> 0 | E14: =+COUNTIFS('Жами топшириқлар-1'!$H$3:$H$5027,B14,'Жами топшириқлар-1'!$I$3:$I$5027,$E$6) -> 0 | F14: =+COUNTIFS('Жами топшириқлар-1'!$H$3:$H$5027,B14,'Жами топшириқлар-1'!$I$3:$I$5027,$F$6) -> 0 | I14: Вилоят, шаҳар ва туман Солиқ бошлиқлари | T14: =+A14 -> 7 | U14: =+B14 -> Э.Нарманов Солиқ (4-сектор) | V14: =+D14/C14 -> #DIV/0! | W14: =+E14/C14 -> #DIV/0! | X14: =+F14/C14 -> #DIV/0!
A15: 8 | B15: Т.Исмаилов ИИБ (3-сектор) | C15: =+D15+E15+F15 -> 0 | D15: =+COUNTIFS('Жами топшириқлар-1'!$H$3:$H$5027,B15,'Жами топшириқлар-1'!$I$3:$I$5027,$D$6) -> 0 | E15: =+COUNTIFS('Жами топшириқлар-1'!$H$3:$H$5027,B15,'Жами топшириқлар-1'!$I$3:$I$5027,$E$6) -> 0 | F15: =+COUNTIFS('Жами топшириқлар-1'!$H$3:$H$5027,B15,'Жами топшириқлар-1'!$I$3:$I$5027,$F$6) -> 0 | I15: Вилоят, шаҳар ва туман ИИБ бошлиқлари | T15: =+A15 -> 8 | U15: =+B15 -> Т.Исмаилов ИИБ (3-сектор) | V15: =+D15/C15 -> #DIV/0! | W15: =+E15/C15 -> #DIV/0! | X15: =+F15/C15 -> #DIV/0!
A16: 9 | B16: З.Назаров | C16: =+D16+E16+F16 -> 186 | D16: =+COUNTIFS('Жами топшириқлар-1'!$H$3:$H$5027,B16,'Жами топшириқлар-1'!$I$3:$I$5027,$D$6) -> 184 | E16: =+COUNTIFS('Жами топшириқлар-1'!$H$3:$H$5027,B16,'Жами топшириқлар-1'!$I$3:$I$5027,$E$6) -> 2 | F16: =+COUNTIFS('Жами топшириқлар-1'!$H$3:$H$5027,B16,'Жами топшириқлар-1'!$I$3:$I$5027,$F$6) -> 0 | I16: Харбий | T16: =+A16 -> 9 | U16: =+B16 -> З.Назаров | V16: =+D16/C16 -> 0.98924731 | W16: =+E16/C16 -> 0.010752688 | X16: =+F16/C16 -> 0
A17: 10 | B17: З.Хидирова | C17: =+D17+E17+F17 -> 55 | D17: =+COUNTIFS('Жами топшириқлар-1'!$H$3:$H$5027,B17,'Жами топшириқлар-1'!$I$3:$I$5027,$D$6) -> 54 | E17: =+COUNTIFS('Жами топшириқлар-1'!$H$3:$H$5027,B17,'Жами топшириқлар-1'!$I$3:$I$5027,$E$6) -> 1 | F17: =+COUNTIFS('Жами топшириқлар-1'!$H$3:$H$5027,B17,'Жами топшириқлар-1'!$I$3:$I$5027,$F$6) -> 0 | I17: Махалла ва оила | T17: =+A17 -> 10 | U17: =+B17 -> З.Хидирова | V17: =+D17/C17 -> 0.98181818 | W17: =+E17/C17 -> 0.018181818 | X17: =+F17/C17 -> 0
A18: 11 | B18: Б.Дониёров | C18: =+D18+E18+F18 -> 66 | D18: =+COUNTIFS('Жами топшириқлар-1'!$H$3:$H$5027,B18,'Жами топшириқлар-1'!$I$3:$I$5027,$D$6) -> 62 | E18: =+COUNTIFS('Жами топшириқлар-1'!$H$3:$H$5027,B18,'Жами топшириқлар-1'!$I$3:$I$5027,$E$6) -> 0 | F18: =+COUNTIFS('Жами топшириқлар-1'!$H$3:$H$5027,B18,'Жами топшириқлар-1'!$I$3:$I$5027,$F$6) -> 4 | I18: Мурожаатлар | T18: =+A18 -> 11 | U18: =+B18 -> Б.Дониёров | V18: =+D18/C18 -> 0.93939394 | W18: =+E18/C18 -> 0 | X18: =+F18/C18 -> 0.060606061
A19: 12 | B19: Ф.Менглиев | C19: =+D19+E19+F19 -> 171 | D19: =+COUNTIFS('Жами топшириқлар-1'!$H$3:$H$5027,B19,'Жами топшириқлар-1'!$I$3:$I$5027,$D$6) -> 171 | E19: =+COUNTIFS('Жами топшириқлар-1'!$H$3:$H$5027,B19,'Жами топшириқлар-1'!$I$3:$I$5027,$E$6) -> 0 | F19: =+COUNTIFS('Жами топшириқлар-1'!$H$3:$H$5027,B19,'Жами топшириқлар-1'!$I$3:$I$5027,$F$6) -> 0 | I19: Вил Кадр | T19: =+A19 -> 12 | U19: =+B19 -> Ф.Менглиев | V19: =+D19/C19 -> 1 | W19: =+E19/C19 -> 0 | X19: =+F19/C19 -> 0
... A21: 14 | B21: Ф.Очилдиев | C21: =+D21+E21+F21 -> 10 | D21: =+COUNTIFS('Жами топшириқлар-1'!$H$3:$H$5027,B21,'Жами топшириқлар-1'!$I$3:$I$5027,$D$6) -> 9 | E21: =+COUNTIFS('Жами топшириқлар-1'!$H$3:$H$5027,B21,'Жами топшириқлар-1'!$I$3:$I$5027,$E$6) -> 0 | F21: =+COUNTIFS('Жами топшириқлар-1'!$H$3:$H$5027,B21,'Жами топшириқлар-1'!$I$3:$I$5027,$F$6) -> 1 | I21: Ахборот тахлил | T21: =+A21 -> 14 | U21: =+B21 -> Ф.Очилдиев | V21: =+D21/C21 -> 0.9 | W21: =+E21/C21 -> 0 | X21: =+F21/C21 -> 0.1
A22: 15 | B22: О.Ашуров | C22: =+D22+E22+F22 -> 9 | D22: =+COUNTIFS('Жами топшириқлар-1'!$H$3:$H$5027,B22,'Жами топшириқлар-1'!$I$3:$I$5027,$D$6) -> 9 | E22: =+COUNTIFS('Жами топшириқлар-1'!$H$3:$H$5027,B22,'Жами топшириқлар-1'!$I$3:$I$5027,$E$6) -> 0 | F22: =+COUNTIFS('Жами топшириқлар-1'!$H$3:$H$5027,B22,'Жами топшириқлар-1'!$I$3:$I$5027,$F$6) -> 0 | T22: =+A22 -> 15 | U22: =+B22 -> О.Ашуров | V22: =+D22/C22 -> 1 | W22: =+E22/C22 -> 0 | X22: =+F22/C22 -> 0
A23: 16 | B23: М.Давлатов | C23: =+D23+E23+F23 -> 27 | D23: =+COUNTIFS('Жами топшириқлар-1'!$H$3:$H$5027,B23,'Жами топшириқлар-1'!$I$3:$I$5027,$D$6) -> 27 | E23: =+COUNTIFS('Жами топшириқлар-1'!$H$3:$H$5027,B23,'Жами топшириқлар-1'!$I$3:$I$5027,$E$6) -> 0 | F23: =+COUNTIFS('Жами топшириқлар-1'!$H$3:$H$5027,B23,'Жами топшириқлар-1'!$I$3:$I$5027,$F$6) -> 0 | T23: =+A23 -> 16 | U23: =+B23 -> М.Давлатов
A24: 17 | B24: Д.Бобоёров | C24: =+D24+E24+F24 -> 1 | D24: =+COUNTIFS('Жами топшириқлар-1'!$H$3:$H$5027,B24,'Жами топшириқлар-1'!$I$3:$I$5027,$D$6) -> 1 | E24: =+COUNTIFS('Жами топшириқлар-1'!$H$3:$H$5027,B24,'Жами топшириқлар-1'!$I$3:$I$5027,$E$6) -> 0 | F24: =+COUNTIFS('Жами топшириқлар-1'!$H$3:$H$5027,B24,'Жами топшириқлар-1'!$I$3:$I$5027,$F$6) -> 0 | T24: =+A24 -> 17 | U24: =+B24 -> Д.Бобоёров
A25: 18 | B25: С.Турдиев Прокуратура (2-сектор) | C25: =+D25+E25+F25 -> 0 | D25: =+COUNTIFS('Жами топшириқлар-1'!$H$3:$H$5027,B25,'Жами топшириқлар-1'!$I$3:$I$5027,$D$6) -> 0 | E25: =+COUNTIFS('Жами топшириқлар-1'!$H$3:$H$5027,B25,'Жами топшириқлар-1'!$I$3:$I$5027,$E$6) -> 0 | F25: =+COUNTIFS('Жами топшириқлар-1'!$H$3:$H$5027,B25,'Жами топшириқлар-1'!$I$3:$I$5027,$F$6) -> 0 | I25: Вилоят, шаҳар ва туман прокурорлари | T25: =+A25 -> 18 | U25: =+B25 -> С.Турдиев Прокуратура (2-сектор) | V25: =+D25/C25 -> #DIV/0! | W25: =+E25/C25 -> #DIV/0! | X25: =+F25/C25 -> #DIV/0!

Sheet Ташкилотлар
A1: Вилоят ҳокими У.Қосимов томонидан ҳудудларни ўрганиш давомида аниқланган муаммоларни бартараф этиш бўйича берилаётган тезкор топшириқларнинг ижроси тўғрисида МАЪЛУМОТ (БАЖАРИЛМАГАН)
C4: 16.08.2025 йил
A5: Т/р | B5: Ташкилот ва идора номи | C5: Бажарилмаган топшириқлар
A6: 1 | B6: “Сурхондарёавтойўл” Ҳудудий йўллардан фойдаланиш ташкилоти директори Хотамов Баходир | C6: 4
A7: =+A6+1 -> 2 | B7: Сурхондарё вилояти Мактабгача ва мактаб таьлими бошқармаси бошлиғи Мамадиев Хусниддин Норбоевич | C7: 3
A8: =+A7+1 -> 3 | B8: Сурхондарё минтақавий йўлларга буюртмачи хизмати давлат унитар корхонаси директори (Умаров Турдимурод Абдураимович) | C8: 3
A9: =+A8+1 -> 4 | B9: Сурхондарё вилоят ҳокимлиги ҳузуридаги “Кичик саноат зоналарини бошқариш ягона дирекцияси” давлат муассасаси директори (Ортиков Бахтияр Бегимкулович) | C9: 3
A10: =+A9+1 -> 5 | B10: Кадастр агентлиги Сурхондарё вилояти бошқармаси бошлиғи Абдирахманов Менглимамат Абдишукурович | C10: 2
A11: =+A10+1 -> 6 | B11: Кадастр агентлиги ҳузуридаги Давлат кадастрлари палатасининг Сурхондарё вилояти бошқармаси бошлиғи в.б Шаймарданов Собир Хушбоқович | C11: 2
A12: =+A11+1 -> 7 | B12: Сурхондарё вилояти соғлиқни сақлаш бошқармаси бошлиғи Абдивохидов Комил Муртазаевич | C12: 2
A13: =+A12+1 -> 8 | B13: Вилоят Марказий банк бош бошқармаси бошлиғи Ражабов Азамат | C13: 2
A14: =+A13+1 -> 9 | B14: “Ҳудудий электр тармоқлари” АЖ Сурхондарё ҳудудий филиали директори Шамсиддинов Маъруфжон Курбонович | C14: 1
A15: =+A14+1 -> 10 | B15: Вилояти Камбағалликни қисқартириш ва бандлик бошқармаси бошлиғи Яқубов Одилжон Алмахамадович | C15: 1
A16: =+A15+1 -> 11 | B16: Сурхондарё вилояти маданият бошқармаси бошлиғи Норбоев Умид | C16: 1
A17: =+A16+1 -> 12 | B17: Бизнесни ривожлантириш банки АТБ Сурхондарё вилояти ҳудудий бошқармаси бошқарувчиси Т.Жўраев | C17: 1
A18: =+A17+1 -> 13 | B18: Сув таъминоти ва оқова сув объектлари қурилиши бўйича инжинеринг компанияси УК вилоят ҳудудий бошқармаси Ж.Аннаматов | C18: 1
... A21: =+A20+1 -> 16 | B21: Вилоят маҳаллалари уюшмаси бошқармаси бошлиғи С.Абдураимов | C21: 1
A22: =+A21+1 -> 17 | B22: Сурхондарё вилояти қурилиш ва уй-жой коммунал хўжалиги бошқармаси (Тангриев Панжи Қобилович)
A23: =+A22+1 -> 18 | B23: Транспорт назорат инспекцияси Х.Абдизоиров
A24: =+A23+1 -> 19 | B24: Туризм бошқармаси бошлиғи ўринбосари Д.Хафизов
A25: =+A24+1 -> 20 | B25: Сурхондарё вилояти қишлоқ хўжалиги бошқармаси бошлиғи ўринбосари Гаппаров Рахматулло Бобохонович
A26: =+A25+1 -> 21 | B26: Миллий банк Мамараджабов Бобур Эргашевич
A27: =+A26+1 -> 22 | B27: Давлат активларини бошқариш агентлигининг Сурхондарё вилояти ҳудудий бошқармаси бошлиғи (Худойбердиев Самандар Каландарович)
A28: =+A27+1 -> 23 | B28: Сурхондарё вилояти спортни ривожлантириш бош бошқармаси бошлиғи в.в.б. Шомуродов Санжар Азамат ўғли
A29: =+A28+1 -> 24 | B29: Насос станциялари, энергетика бошқармаси Т.Кучкинов (УНС)
A30: =+A29+1 -> 25 | B30: Вилоят ветеринария ва чорвачиликни ривожлантириш бошқармаси А.Юсупов
A31: =+A30+1 -> 26 | B31: “Ўзсаноатқурилишбанк” АТБ Сурхондарё минтақавий филиал бошлиғи С.Абдурахмонов
A32: =+A31+1 -> 27 | B32: Сурхондарё вилояти ҳокимлиги ҳузуридаги “Ягона буюртмачи хизмати” ДУК директори Йулдошев Ахмад Асодович
A33: =+A32+1 -> 28 | B33: Инфратузилмани ривожлантириш инженеринг компанияси давлат муассаси Сурхондарё вилояти ҳудудий бўлинмаси бошлиғи Зоиров Махмуд Абдураимович
... A73: =+A72+1 -> 68 | B73: Халқ қабулхонаси
A74: ЖАМИ | C74: =SUM(C6:C72) -> 29

Sheet Туманлар
A1: Вилоят ҳокими У.Қосимов томонидан ҳудудларни ўрганиш давомида аниқланган муаммоларни бартараф этиш бўйича берилаётган тезкор топшириқларнинг ижроси тўғрисида МАЪЛУМОТ (БАЖАРИЛМАГАН)
E4: 28.10.2025 йил
A5: Т\Р | B5: Масъуллар | C5: Бажарилмаган топшириқ сони | D5: Шундан | F5: Изох
D6: Туман ижрочи | E6: Вилоят, Шаҳар ва туман ҳокимликлари биргаликда
A7: 1 | B7: Термиз шаҳар | C7: =+D7+E7 -> 21 | D7: 21 | N7: 1 | O7: Термиз шаҳар
A8: =+A7+1 -> 2 | B8: Ангор тумани | C8: =+D8+E8 -> 0 | N8: 2 | O8: Ангор тумани
A9: =+A8+1 -> 3 | B9: Бандихон тумани | C9: =+D9+E9 -> 0 | N9: 3 | O9: Бандихон тумани
A10: =+A9+1 -> 4 | B10: Бойсун тумани | C10: =+D10+E10 -> 0 | N10: 4 | O10: Бойсун тумани
A11: =+A10+1 -> 5 | B11: Денов тумани | C11: =+D11+E11 -> 0 | N11: 5 | O11: Денов тумани
A12: =+A11+1 -> 6 | B12: Жарқурғон тумани | C12: =+D12+E12 -> 0 | N12: 6 | O12: Жарқурғон тумани
A13: =+A12+1 -> 7 | B13: Қизириқ тумани | C13: =+D13+E13 -> 0 | N13: 7 | O13: Қизириқ тумани
A14: =+A13+1 -> 8 | B14: Қумқўрғон тумани | C14: =+D14+E14 -> 0 | N14: 8 | O14: Қумқўрғон тумани
A15: =+A14+1 -> 9 | B15: Музработ тумани | C15: =+D15+E15 -> 0 | N15: 9 | O15: Музработ тумани
A16: =+A15+1 -> 10 | B16: Олтинсой тумани | C16: =+D16+E16 -> 0 | N16: 10 | O16: Олтинсой тумани
A17: =+A16+1 -> 11 | B17: Сариосиё тумани | C17: =+D17+E17 -> 0 | N17: 11 | O17: Сариосиё тумани
A18: =+A17+1 -> 12 | B18: Термиз тумани | C18: =+D18+E18 -> 0 | N18: 12 | O18: Термиз тумани
A19: =+A18+1 -> 13 | B19: Узун тумани | C19: =+D19+E19 -> 0 | N19: 13 | O19: Узун тумани
... A21: =+A20+1 -> 15 | B21: Шўрчи тумани | C21: =+D21+E21 -> 0 | N21: 15 | O21: Шўрчи тумани
A22: ЖАМИ | C22: =SUM(C7:C21) -> 21 | D22: =SUM(D7:D21) -> 21 | E22: =SUM(E7:E21) -> 0 | L22: =SUM(L7:L21) -> 0 | N22: ЖАМИ | P22: =SUM(P7:P21) -> 0

Sheet ташкилот тушунтириш хати
A1: Вилоят ҳокими У.Қосимов томонидан ҳудудларни ўрганиш давомида аниқланган муаммоларни бартараф этиш бўйича берилаётган тезкор топшириқларнинг ижроси тўғрисида МАЪЛУМОТ (БАЖАРИЛМАГАН)
F4: 21.10.2024 йил
A5: Т/р | B5: Топшириқларнинг ижросига масъул бўлган ташкилот ва идоралар | C5: Бажарилмаган топшириқлар | D5: Тушунтириш хатлари тақдим этилиши | E5: Мажмуа номи
A6: 1 | B6: “Сурхондарёавтойўл” Ҳудудий йўллардан фойдаланиш ташкилоти директори Хотамов Баходир Чоршамиевич | C6: 7 | D6: тақдим этилди | E6: А.Амиров | F6: Қурилиш мажмуаси
A7: =+A6+1 -> 2 | B7: Сурхондарё вилояти Мактабгача ва мактаб таьлими бошқармаси бошлиғи Мамадиев Хусниддин Норбоевич | C7: 7 | D7: тақдим этилмади | E7: И.Сапаров | F7: Ёшлар мажмуаси
A8: =+A7+1 -> 3 | B8: “Ҳудудий электр тармоқлари” АЖ Сурхондарё ҳудудий филиали директори Шамсиддинов Маъруфжон Курбонович | C8: 3 | D8: тақдим этилди | E8: А.Амиров | F8: Қурилиш мажмуаси
A9: =+A8+1 -> 4 | B9: Вилоят ва туман (шаҳар) прокуратураси
A10: 4 | B10: Сурхондарё вилояти ҳокимлиги ҳузуридаги “Ягона буюртмачи хизмати” ДУК директори Йулдошев Ахмад Асодович | C10: 2 | D10: тақдим этилди | E10: А.Амиров | F10: Қурилиш мажмуаси
A11: =+A10+1 -> 5 | B11: Сурхондарё вилояти солиқ бошқармаси (Нарманов Эркин Абдуалимович) | C11: 2 | D11: тақдим этилди | E11: Иқтисодиёт мажмуаси | F11: Иқтисодиёт мажмуаси
A12: =+A11+1 -> 6 | B12: Кадастр агентлиги ҳузуридаги Давлат кадастрлари палатасининг Сурхондарё вилояти бошқармаси бошлиғи (Сувонов Шаҳобиддин Мусурмон ўғли) | C12: 1 | D12: тақдим этилди | E12: Иқтисодиёт мажмуаси | F12: Иқтисодиёт мажмуаси
A13: =+A12+1 -> 7 | B13: Кадастр агентлиги Сурхондарё вилояти бошқармаси бошлиғи (Абдирахманов Менглимамат Абдишукурович) | C13: 1 | D13: тақдим этилди | E13: Ш.Ражабов | F13: Иқтисодиёт мажмуаси
A14: =+A13+1 -> 8 | B14: “Агробанк” акциядорик тижорат банкининг Сурхондарё вилояти бошқармаси бошлиғи Раджабов Шухрат Бахтиёрович | C14: 1 | D14: тақдим этилди | E14: Ш.Ражабов | F14: Иқтисодиёт мажмуаси
A15: =+A14+1 -> 9 | B15: Сурхондарё вилояти “Агропилла” масъулияти чекланган жамияти раиси Абдуллаев Акмал Абдусалимович | C15: 1 | D15: тақдим этилмади | E15: Ф.Исмоилов | F15: Қишлоқ хўжалиги мажмуаси
A16: =+A15+1 -> 10 | B16: Туронбанк акциядорлик-тижорат банки Сурхондарё банк хизматлар маркази рахбари Маматалиев Искандар Рашидович | C16: 1 | D16: тақдим этилди | E16: Ш.Ражабов | F16: Иқтисодиёт мажмуаси
A17: =+A16+1 -> 11 | B17: Вилоят ва туман (шаҳар) ИИБ (Исмаилов Тимур Камалатдинович)
A18: 11 | B18: Ичимлик сув ва оқова сув қурилиши бўйича ИК Б.Имомов | C18: 1 | D18: тақдим этилди | E18: А.Амиров | F18: Қурилиш мажмуаси
A19: =+A18+1 -> 12 | B19: Сурхондарё вилояти қурилиш соҳасидаги худудий назорат инспекцияси бошлиғи Лолаев Шарофиддин Усанович (ГАСН) | C19: 1 | D19: тақдим этилди | E19: А.Амиров | F19: Қурилиш мажмуаси
A20: =+A19+1 -> 13 | B20: Сурхондарё вилояти қурилиш ва уй-жой коммунал хўжалиги бошқармаси (Тангиров Панжи Қобилович)
A21: =+A20+1 -> 14 | B21: Вилоят маҳаллалари уюшмаси бошқармаси бошлиғи С.Абдураимов
A22: =+A21+1 -> 15 | B22: “Аму-Сурхон” ирригация тизимлари хавза бошкармаси бошлиғи Б.Алимов,
A23: =+A22+1 -> 16 | B23: Бизнесни ривожлантириш банки АТБ Сурхондарё вилояти ҳудудий бошқармаси бошқарувчиси (Утаганов Мамур Иргашович)
A24: =+A23+1 -> 17 | B24: Сурхондарё вилояти қишлоқ хўжалиги бошқармаси бошлиғи Гаппаров Рахматулло Бобохонович
A25: =+A24+1 -> 18 | B25: Сурхондарё вилояти соғлиқни сақлаш бошқармаси бошлиғи (Абдивохидов Комил Муртазаевич)
A26: =+A25+1 -> 19 | B26: Сурхондарё минтақавий йўлларга буюртмачи хизмати давлат унитар корхонаси директори (Умаров Турдимурод Абдураимович)
A27: =+A26+1 -> 20 | B27: Сурхондарё вилояти Иқтисодиёт ва молия бош бошқармаси бошлиғи Нормуминов Жуманазар Равшанович
A28: =+A27+1 -> 21 | B28: “Ҳудудгаз Сурхондарё” газ таъминоти филиали директори Мансуров Мирзоқул Абдухофизович
A29: =+A28+1 -> 22 | B29: Сурхондарё вилояти Фавқулотда вазиятлар бошқармаси бошлиғи в.в.б. Дарханов Муроджон Қурбонназарович
A30: =+A29+1 -> 23 | B30: Сурхондарё вилоят ҳокимлиги ҳузуридаги “Кичик саноат зоналарини бошқариш ягона дирекцияси” давлат муассасаси директори (Ортиков Бахтияр Бегимкулович)
A31: =+A30+1 -> 24 | B31: Ўзбекистон Республикаси Бош прокуратураси ҳузуридаги Мажбурий ижро бюросининг Сурхондарё вилояти бошқармаси бошлиғи (Халмуратов Азамат Пайзилович)
... A45: =+A44+1 -> 38 | B45: Халқ қабулхонаси
A46: ЖАМИ | C46: =SUM(C6:C44) -> 28
B47: Тушунтириш хатлари

Sheet туман тушунтириш хати
A1: Вилоят ҳокими У.Қосимов томонидан ҳудудларни ўрганиш давомида аниқланган муаммоларни бартараф этиш бўйича берилаётган тезкор топшириқларнинг ижроси тўғрисида МАЪЛУМОТ (БАЖАРИЛМАГАН)
E4: 04.10.2024 йил
A5: Т\Р | B5: Масъуллар | C5: Бажарилмаган топшириқ сони | D5: Тушунтириш хатлари тақдим этилиши | E5: Изох
A7: 1 | B7: Ангор тумани | C7: 4 | D7: тақдим этилди | M7: 1 | N7: Термиз шаҳар
A8: =+A7+1 -> 2 | B8: Бандихон тумани | C8: 6 | D8: тақдим этилди | M8: 2 | N8: Ангор тумани
A9: =+A8+1 -> 3 | B9: Бойсун тумани | C9: 5 | D9: тақдим этилди | M9: 3 | N9: Бандихон тумани
A10: =+A9+1 -> 4 | B10: Денов тумани | C10: 4 | D10: тақдим этилди | M10: 4 | N10: Бойсун тумани
A11: =+A10+1 -> 5 | B11: Жарқурғон тумани | C11: 5 | D11: тақдим этилди | M11: 5 | N11: Денов тумани
A12: =+A11+1 -> 6 | B12: Қизириқ тумани | C12: 2 | D12: тақдим этилмади | M12: 6 | N12: Жарқурғон тумани
A13: =+A12+1 -> 7 | B13: Қумқўрғон тумани | C13: 3 | D13: тақдим этилди | M13: 7 | N13: Қизириқ тумани
A14: =+A13+1 -> 8 | B14: Музработ тумани | C14: 9 | D14: тақдим этилмади | M14: 8 | N14: Қумқўрғон тумани
A15: =+A14+1 -> 9 | B15: Олтинсой тумани | C15: 4 | D15: тақдим этилди | M15: 9 | N15: Музработ тумани
A16: =+A15+1 -> 10 | B16: Сариосиё тумани | C16: 6 | D16: тақдим этилмади | M16: 10 | N16: Олтинсой тумани
A17: =+A16+1 -> 11 | B17: Термиз тумани | C17: 4 | D17: тақдим этилди | M17: 11 | N17: Сариосиё тумани
A18: =+A17+1 -> 12 | B18: Термиз шаҳар | C18: 5 | D18: тақдим этилмади | M18: 12 | N18: Термиз тумани
A19: =+A18+1 -> 13 | B19: Узун тумани | C19: 4 | D19: тақдим этилмади | M19: 13 | N19: Узун тумани
... A21: =+A20+1 -> 15 | B21: Шўрчи тумани | C21: 3 | D21: тақдим этилди | M21: 15 | N21: Шўрчи тумани
A22: ЖАМИ | C22: =SUM(C7:C21) -> 68 | D22: =SUM(D7:D21) -> 0 | K22: =SUM(K7:K21) -> 0 | M22: ЖАМИ | O22: =SUM(O7:O21) -> 0

Sheet Каттага бажарилган
A1: Вилоят ҳокими У.Қосимов томонидан ҳудудларни ўрганиш давомида аниқланган муаммоларни бартараф этиш бўйича берилаётган тезкор топшириқларнинг ижроси тўғрисида МАЪЛУМОТ (24.05.2023) Бажарилган
A3: Т/Р | B3: Банд | C3: Топшириқ берилган сана | D3: Топшириқ берилган жой | E3: Топшириқ мазмуни | F3: Ижро муддати | G3: Асосий ижрочи маъсуллар | H3: Вилоят ҳокимлиги, шаҳар ва туман ҳокимликлари масъуллар
A4: 1 | B4: 649 | C4: 17.01.2023 | D4: Шўрчи тумани | E4: Шўрчи тумани "Мустақиллик" МФЙдаги саломатлик йўлакларини қайта қуриш ёки бурчатка териш. | F4: 45066 | G4: Шўрчи тумани ҳокими | H4: Шўрчи тумани
A5: 2 | B5: 735 | C5: 21.01.2023 | D5: Штаб йиғилиш | E5: 1 апрелга қадар санъаткорларни тўлиқ лицензия олган ҳолда ишлаши масаласини якунлаш. | F5: 45020 | G5: “Ўзбекконцерт” давлат муассасаси Сурхондарё вилояти бўлими (И.Темиров). | H5: Ж.Тўраев
A6: 3 | B6: 761 | C6: 21.01.2023 | D6: Ангор тумани | E6: Бандихон, Шўрчи, Қумқўрғон туманлари ва Термиз шаҳрида арзон уй-жойлар қуриш ишларини бошлаш. | F6: 45066 | G6: Вилоят Халқ қабулхонаси (А.Эшмуродов), Қурилиш бошқармаси (К.Эшматов). Бандихон, Шўрчи, Қумқўрғон туманлари ва Термиз шаҳар хокимликлари | H6: А.Хидиров
A7: 4 | B7: 879 | C7: 29.01.2023 | D7: Узун тумани | E7: Узун туманидаги мавжуд 46 та кўп қаватли уй-жойларда таъмирлаш ва ободонлаштириш ишларини якунлаш. | F7: 45036 | G7: Узун тумани ҳокими ва сектор раҳбарлари. | H7: Узун тумани
A8: 5 | B8: 1023 | C8: 05.02.2023 | D8: Денов туманида семинар | E8: Туман ва шаҳарларда 1 тадан маҳаллаларни муқобил энергияга ўтказиш бўйича намунавий қилиш. | F8: 20.03.2023 | G8: Ангор, Жарқўрғон, Қизириқ, Музработ, Олтинсой, Узун, Термиз туман, туман ҳокимлари | H8: Шаҳар ва туман ҳокимликлари
A9: 6 | B9: 1212 | C9: 44995 | D9: Зоом йиғилиш | E9: Қумқўрғон туманидаги 4 та сектор котибларига хайфсан берилсин ва ойлик иш хақини 30 % миқдорида жарима жазоси қўлланилсин. | F9: 44996 | G9: Қумқўрғон тумани ҳокими ва сектор раҳбарлари. | H9: Қумқўрғон тумани
A10: 7 | B10: 1233 | C10: 45000 | D10: Шеробод тумани | E10: Шеробод тумани "Мехробод" махалласидаги уйи ёнган фуқаро Жумаев Мансурга (90-721-21-80) 20 т цемент, 30 минг дона ғишт ва страпллар етказиб бериш. | F10: 45066 | G10: Вилоят хокимининг ўринбосари А.Хидиров, Туман ИИБ | H10: А.Хидиров
A11: 8 | B11: 1351 | C11: 01.04.2023 | D11: Қишлоқ хўжалиги бўйича селектр | E11: Денов туманида фермер хўжаликларининг (йиғилишга кечикиб киран 2 та фермернинг) ер майдонини давлат захирасига қайтариш. | F11: 45061 | G11: Денов тумани ҳокими, Денов тумани прокурори. | H11: Денов тумани
A12: 9 | B12: 1415 | C12: 45031 | D12: Жарқўрғон тумани | E12: Ўзбекистон Республикаси Президентининг ПҚ-57-сонли қарорнинг 2-иловасига мувофиқ ижтимоий соҳа обйектлари ва давлат идораларида кичик қувватдаги панеллар ўрнатиш ишларни ташкиллаштирмаганлиги сабабли Бойсун ва Узун туманлари ҳокимларининг биринчи ўринбосарларига ҳайфсан интизомий жазоси берилсин ҳамда Олтинсой ва Бандихон туманлари ҳокимларининг биринчи ўринбосарлари огоҳлантирилсин | F12: 45040 | G12: Олтинсой туман хокимлари | H12: Шаҳар ва туман ҳокимликлари
A13: 10 | B13: 1420 | C13: 45031 | D13: Жарқўрғон тумани | E13: Ўзбекистон Республикаси Президентининг ПҚ-57-сонли қарорнинг 7-иловасига мувофиқ ижтимоий соҳа обйектларининг локал иситиш тизимларини кўмир ёқилғисига ўтказиш бўйича топшириқлар ижроси ўз ҳолига ташлаб қўйилганлиги сабабли вилоят Иқтисодиёт ва молия бош бошқармаси бошлиғи вазифасини вақтинча бажарувчиси Ж.Нормўминов, Олтинсой тумани Иқтисодиёт ва молия бўлими бошлиғи Ж.Жўрайев ҳамда Денов тумани Иқтисодиёт ва молия бўлими бошлиғи А.Мухаммадиевларга ҳайфсан интизомий жазоси берилсин. | F13: 45040 | G13: Олтинсой тумани хокимлиги | H13: Олтинсой тумани
A14: 11 | B14: 1429 | C14: 45020 | D14: Шеробод тумани | E14: Шеробод туманида бозор рўпарасидаги автошохбекат ҳамда ер ости тунел йўлини реконструкция қилиш. Машиналарни жойлашувини автошохбекатга кўчириш. | F14: 45066 | G14: Шеробод туман хокими, туман прокурори, туман ИИБ бошлиғи, | H14: Шеробод тумани
A15: 12 | B15: 1440 | C15: 45038 | D15: Шеробод тумани | E15: Шеробод тумани бозор қаршисидаги ва атрофидаги кўп қаватли уй-жойларга сув чиқариш. (Бозорова Фотима 99-150-64-65) | F15: 45056 | G15: Шеробод туман хокими З.Халилов ва туман сектор раҳбарлари | H15: Шеробод тумани
A16: 13 | B16: 1453 | C16: 45042 | D16: Қишлоқ хўжалиги бўйича ўтказилган йиғилиш | E16: Вилоя солиқ 144 та фермер хўжалигини хисоб рақамларини очиш | F16: 45050 | G16: Вилоят ДСИ бошлиғи Э.Нарманов | H16: Ф.Исмоилов
